2020-05-12 13:43:18.531 [error] <0.476.0> Supervisor 'Elixir.Conference.Supervisor' had child 'Elixir.Conference.Consumer' started with 'Elixir.Conference.Consumer':start_link([]) at undefined exit with reason {'EXIT',{undef,[{'Elixir.Conference.Consumer',start_link,[[]],[]},{supervisor,do_start_child_i,3,[{file,"supervisor.erl"},{line,379}]},{supervisor,do_start_child,2,[{file,"supervisor.erl"},{line,365}]},{supervisor,'-start_children/2-fun-0-',3,[{file,"supervisor.erl"},{line,349}]},{supervisor,children_map,4,[{file,"supervisor.erl"},{line,1157}]},{supervisor,init_children,2,[{file,"supervisor.erl"},{line,315}]},{gen_server,init_it,2,[{file,"gen_server.erl"},{line,374}]},{gen_server,init_it,6,[...]}]}} in context start_error
2020-05-12 13:43:18.532 [error] <0.474.0> CRASH REPORT Process <0.474.0> with 0 neighbours exited with reason: {{shutdown,{failed_to_start_child,'Elixir.Conference.Consumer',{'EXIT',{undef,[{'Elixir.Conference.Consumer',start_link,[[]],[]},{supervisor,do_start_child_i,3,[{file,"supervisor.erl"},{line,379}]},{supervisor,do_start_child,2,[{file,"supervisor.erl"},{line,365}]},{supervisor,'-start_children/2-fun-0-',3,[{file,"supervisor.erl"},{line,349}]},{supervisor,children_map,4,[{file,"supervisor.erl"},{line,1157}]},{supervisor,init_children,2,[{file,"supervisor.erl"},{line,315}]},{gen_server,init_it,...},...]}}}},...} in application_master:init/4 line 138
2020-05-12 14:52:46.643 [error] <0.393.0> Supervisor 'Elixir.Conference.Supervisor' had child 'Elixir.Conference.Consumer' started with 'Elixir.Conference.Consumer':start_link([]) at undefined exit with reason {'EXIT',{undef,[{'Elixir.Conference.Consumer',start_link,[[]],[]},{supervisor,do_start_child_i,3,[{file,"supervisor.erl"},{line,379}]},{supervisor,do_start_child,2,[{file,"supervisor.erl"},{line,365}]},{supervisor,'-start_children/2-fun-0-',3,[{file,"supervisor.erl"},{line,349}]},{supervisor,children_map,4,[{file,"supervisor.erl"},{line,1157}]},{supervisor,init_children,2,[{file,"supervisor.erl"},{line,315}]},{gen_server,init_it,2,[{file,"gen_server.erl"},{line,374}]},{gen_server,init_it,6,[...]}]}} in context start_error
2020-05-12 14:52:46.644 [error] <0.391.0> CRASH REPORT Process <0.391.0> with 0 neighbours exited with reason: {{shutdown,{failed_to_start_child,'Elixir.Conference.Consumer',{'EXIT',{undef,[{'Elixir.Conference.Consumer',start_link,[[]],[]},{supervisor,do_start_child_i,3,[{file,"supervisor.erl"},{line,379}]},{supervisor,do_start_child,2,[{file,"supervisor.erl"},{line,365}]},{supervisor,'-start_children/2-fun-0-',3,[{file,"supervisor.erl"},{line,349}]},{supervisor,children_map,4,[{file,"supervisor.erl"},{line,1157}]},{supervisor,init_children,2,[{file,"supervisor.erl"},{line,315}]},{gen_server,init_it,...},...]}}}},...} in application_master:init/4 line 138
2020-05-12 16:32:19.806 [error] <0.387.0> Failed to start Ranch listener 'Elixir.Conference.Plug.Router.HTTP' in ranch_tcp:listen([{cacerts,'...'},{key,'...'},{cert,'...'},{port,4000}]) for reason eaddrinuse (address already in use)
2020-05-12 16:32:19.812 [error] <0.387.0> CRASH REPORT Process <0.387.0> with 0 neighbours exited with reason: {listen_error,'Elixir.Conference.Plug.Router.HTTP',eaddrinuse} in ranch_acceptors_sup:listen_error/5 line 66
2020-05-12 16:35:38.942 [error] <0.386.0> Failed to start Ranch listener 'Elixir.Conference.Plug.Router.HTTP' in ranch_tcp:listen([{cacerts,'...'},{key,'...'},{cert,'...'},{port,4000}]) for reason eaddrinuse (address already in use)
2020-05-12 16:35:38.948 [error] <0.386.0> CRASH REPORT Process <0.386.0> with 0 neighbours exited with reason: {listen_error,'Elixir.Conference.Plug.Router.HTTP',eaddrinuse} in ranch_acceptors_sup:listen_error/5 line 66
2020-05-12 16:35:38.948 [error] <0.384.0> Supervisor {<0.384.0>,ranch_listener_sup} had child ranch_acceptors_sup started with ranch_acceptors_sup:start_link('Elixir.Conference.Plug.Router.HTTP', ranch_tcp) at undefined exit with reason {listen_error,'Elixir.Conference.Plug.Router.HTTP',eaddrinuse} in context start_error
2020-05-12 16:35:38.949 [error] <0.383.0> Supervisor 'Elixir.Conference.Supervisor' had child {ranch_listener_sup,'Elixir.Conference.Plug.Router.HTTP'} started with ranch_listener_sup:start_link('Elixir.Conference.Plug.Router.HTTP', ranch_tcp, #{max_connections => 16384,num_acceptors => 100,socket_opts => [{port,4000}]}, cowboy_clear, #{env => #{dispatch => [{'_',[],[{'_',[],'Elixir.Plug.Cowboy.Handler',{'Elixir.Conference.Plug.Router',...}}]}]},...}) at undefined exit with reason {shutdown,{failed_to_start_child,ranch_acceptors_sup,{listen_error,'Elixir.Conference.Plug.Router.HTTP',eaddrinuse}}} in context start_error
2020-05-12 16:47:24.020 [error] <0.384.0> Supervisor 'Elixir.Conference.Supervisor' had child 'Elixir.Conference.Consumer' started with 'Elixir.Conference.Consumer':start_link([]) at undefined exit with reason {{shutdown,{server_initiated_close,406,<<"PRECONDITION_FAILED - inequivalent arg 'x-dead-letter-exchange' for queue 'gen_server_test_queue' in vhost '/': received none but current is the value '' of type 'longstr'">>}},{gen_server,call,[<0.502.0>,{call,{'queue.declare',0,<<"gen_server_test_queue">>,false,true,false,false,false,[]},none,<0.488.0>},60000]}} in context start_error
2020-05-12 16:56:24.066 [error] <0.488.0> CRASH REPORT Process <0.488.0> with 0 neighbours exited with reason: {{shutdown,{server_initiated_close,406,<<"PRECONDITION_FAILED - inequivalent arg 'x-dead-letter-exchange' for queue 'gen_server_test_queue' in vhost '/': received none but current is the value '' of type 'longstr'">>}},{gen_server,call,[<0.502.0>,{call,{'queue.declare',0,<<"gen_server_test_queue">>,false,true,false,false,false,[]},none,<0.488.0>},60000]}} in gen_server:call/3 line 223
2020-05-12 16:57:52.665 [error] <0.384.0> Supervisor 'Elixir.Conference.Supervisor' had child 'Elixir.Conference.Consumer' started with 'Elixir.Conference.Consumer':start_link([]) at undefined exit with reason {{shutdown,{server_initiated_close,406,<<"PRECONDITION_FAILED - inequivalent arg 'x-dead-letter-exchange' for queue 'gen_server_test_queue' in vhost '/': received none but current is the value '' of type 'longstr'">>}},{gen_server,call,[<0.502.0>,{call,{'queue.declare',0,<<"gen_server_test_queue">>,false,true,false,false,false,[]},none,<0.488.0>},60000]}} in context start_error
2020-05-12 16:58:13.491 [error] <0.488.0> CRASH REPORT Process <0.488.0> with 0 neighbours exited with reason: {{shutdown,{server_initiated_close,406,<<"PRECONDITION_FAILED - inequivalent arg 'x-dead-letter-exchange' for queue 'gen_server_test_queue' in vhost '/': received none but current is the value '' of type 'longstr'">>}},{gen_server,call,[<0.502.0>,{call,{'queue.declare',0,<<"gen_server_test_queue">>,false,true,false,false,false,[]},none,<0.488.0>},60000]}} in gen_server:call/3 line 223
2020-05-12 17:01:18.348 [error] <0.384.0> Supervisor 'Elixir.Conference.Supervisor' had child 'Elixir.Conference.Consumer' started with 'Elixir.Conference.Consumer':start_link([]) at undefined exit with reason {{shutdown,{server_initiated_close,406,<<"PRECONDITION_FAILED - inequivalent arg 'x-dead-letter-exchange' for queue 'gen_server_test_queue' in vhost '/': received none but current is the value '' of type 'longstr'">>}},{gen_server,call,[<0.502.0>,{call,{'queue.declare',0,<<"gen_server_test_queue">>,false,true,false,false,false,[]},none,<0.488.0>},60000]}} in context start_error
2020-05-12 17:01:18.349 [error] <0.488.0> CRASH REPORT Process <0.488.0> with 0 neighbours exited with reason: {{shutdown,{server_initiated_close,406,<<"PRECONDITION_FAILED - inequivalent arg 'x-dead-letter-exchange' for queue 'gen_server_test_queue' in vhost '/': received none but current is the value '' of type 'longstr'">>}},{gen_server,call,[<0.502.0>,{call,{'queue.declare',0,<<"gen_server_test_queue">>,false,true,false,false,false,[]},none,<0.488.0>},60000]}} in gen_server:call/3 line 223
2020-05-12 20:49:12.052 [error] <0.514.0> gen_server <0.514.0> terminated with reason: {socket_error,timeout}
2020-05-12 20:49:12.053 [error] <0.508.0> gen_server <0.508.0> terminated with reason: {socket_error,timeout}
2020-05-12 20:49:12.055 [error] <0.508.0> CRASH REPORT Process <0.508.0> with 0 neighbours exited with reason: {socket_error,timeout} in gen_server:handle_common_reply/8 line 751
2020-05-12 20:49:12.056 [error] <0.506.0> Supervisor {<0.506.0>,amqp_connection_sup} had child connection started with amqp_gen_connection:start_link(<0.507.0>, {amqp_params_network,<<"guest">>,<<"rV+WLu8hL+90XoVSWCdzLdCIFbR+lb0ua4urwf9bwa6zadzhEUDb9pydvqEKZW...">>,...}) at <0.508.0> exit with reason {socket_error,timeout} in context child_terminated
2020-05-12 20:49:12.057 [error] <0.506.0> Supervisor {<0.506.0>,amqp_connection_sup} had child connection started with amqp_gen_connection:start_link(<0.507.0>, {amqp_params_network,<<"guest">>,<<"rV+WLu8hL+90XoVSWCdzLdCIFbR+lb0ua4urwf9bwa6zadzhEUDb9pydvqEKZW...">>,...}) at <0.508.0> exit with reason reached_max_restart_intensity in context shutdown
